Workbook

Sheet Study Guide
A1: ETERNAL LTD. — STUDY GUIDE
A2: Purpose | B2: This is an undergraduate investment-research project. The aim is to understand how Eternal could create value across food delivery, quick commerce, going-out and B2B supplies.
A3: Main question | B3: Does the multi-business ecosystem create economic value, or is it just a collection of different businesses?
A5: THE MODEL IN ONE LINE | B5: Historical numbers → operating assumptions → forecast → DCF/SOTP → investment conclusion
A7: STEP 1 — Understand the businesses | B7: Zomato = food delivery; Blinkit = quick commerce; District = going-out; Hyperpure = B2B supplies.
A8: STEP 2 — Look at history | B8: Start with FY23–FY26 and ask: Is revenue growing? Are margins improving? Which business is driving growth?
A9: STEP 3 — Forecast the businesses | B9: For each major business, estimate growth and an eventual EBITDA margin. These are my assumptions, not company guidance.
A10: STEP 4 — Build group EBITDA | B10: Revenue × EBITDA margin gives a simple operating-profit view. Then combine the businesses.
A11: STEP 5 — Value the company | B11: DCF asks: What are future cash flows worth today? SOTP asks: What if each business is valued separately?
A12: STEP 6 — Compare with market price | B12: Compare my estimated value per share with the current share price. Then decide what the market seems to be assuming.
A14: NUMBERS I MUST KNOW | B14: Current share price: ₹316.80 | Base DCF: ~₹187/share | Base SOTP: ~₹258/share | Blended: ~₹223/share
A15: CORE INVESTMENT QUESTION | B15: The biggest debate in my model is whether Blinkit can keep growing rapidly while eventually reaching sustainable EBITDA margins.
A17: WORDS TO KNOW | B17: NOV = Net Order Value. EBITDA = operating profit before depreciation, interest and tax. DCF = Discounted Cash Flow. SOTP = Sum-of-the-Parts. WACC = discount rate used for DCF. Terminal value = value of cash flows after the explicit forecast period.
A19: WHAT I SHOULD NOT MEMORISE | B19: Do not memorise every cell. Understand why the number is there, what assumption drives it, and what happens if that assumption changes.

Sheet Cover
A1: ETERNAL LTD.
A2: Undergraduate Investment Research Project
A3: Prepared by : Gayathri Sudhir
A5: October 2026
A7: Eternal: From Food-Delivery Platform to Multi-Product Consumer Ecosystem
A8: Does Eternal's multi-product ecosystem actually create economic value, or is it simply adding businesses under one corporate umbrella?
A10: KEY OUTPUTS (live — active scenario)
A11: Active scenario | B11: =Assumptions!B32 -> Base
A12: Market price used (₹) | B12: =Assumptions!B19 -> 316.8
A13: DCF value per share (₹) | B13: =Valuation!B43 -> 187.46575
A14: SOTP value per share (₹) | B14: =Valuation!G74 -> 258.3627
A15: Blended value per share (₹) | B15: =Valuation!G77 -> 222.91422
A16: Blended upside / (downside) | B16: =B15/B12-1 -> -0.29635662
A17: WACC | B17: =Assumptions!B13 -> 0.133
A18: Terminal growth | B18: =Assumptions!B16 -> 0.05
A19: FY29E Adj. EBITDA (US$ mn) vs management $1bn goal | B19: ='Operating Model'!F113 -> 971.10099
A21: MODEL CHECKS (all should read OK)
A22: Historical P&L ties to reported PBT and PAT | B22: =IF(AND(SUM(Historical!E34:G34)=0,SUM(Historical!D36:G36)=0),"OK","CHECK") -> OK
A23: Quarterly segment Adj. EBITDA sums to company-reported total | B23: =IF(SUMPRODUCT(ABS('Operating Model'!B27:K27))=0,"OK","CHECK") -> OK
A24: FY26 reported EBITDA + SBC = reported segment results | B24: =IF(AND('Operating Model'!B54=0,'Operating Model'!C54=0),"OK","CHECK") -> OK
A25: Forecast base year ties to quarterly tables | B25: =IF(AND('Operating Model'!C119=0,'Operating Model'!C120=0),"OK","CHECK") -> OK
A26: WACC > terminal growth | B26: =IF(Assumptions!B13>Assumptions!B16,"OK","CHECK") -> OK
A27: Sensitivity-1 centre cell equals DCF value per share | B27: =IF(Valuation!B60=0,"OK","CHECK") -> OK
A29: CONTENTS
A30: Assumptions | B30: WACC, market data, scenario selector (Bear/Base/Bull), operating drivers, SOTP multiples. Every judgement is labelled.
A31: Historical | B31: FY21–FY26 income statement from filings with tie-outs to reported PBT/PAT.
A32: Operating Model | B32: Quarterly segment KPIs, EBITDA bridge, 10-year segment forecast (Zomato, Blinkit, District, Hyperpure, Others).
A33: Valuation | B33: DCF, WACC×g sensitivity, SOTP, scenario summary, further sensitivities and investment thesis.
A34: Mini Projects | B34: 1) Customer LTV 2) Advertising economics 3) Zomato vs Swiggy cross-sell 4) Blinkit implied valuation.
A35: Sources | B35: Every source with Primary/Secondary/Assumption tag, plus open items.
A37: COLOUR CODE
A38: Blue = hardcoded input
A39: Black = formula
A40: Green = link to another sheet
A41: Yellow fill = key judgement assumption (not disclosed)
A42: Study order: Study Guide → Historical → Operating Model → Valuation → Mini Projects → Sources
A43: Educational research project. Not investment advice. Figures marked Secondary or Assumption must be verified before relying on them.

Sheet Assumptions
A1: ETERNAL LTD. — ASSUMPTIONS
A2: Blue = hardcoded input | Black = formula | Green = link to other sheet | Yellow fill = key assumption (judgement, not disclosed). ₹ crore unless stated.
A3: Model Date | B3: 46303 | F3: Date the model inputs were refreshed.
A4: Forecast Period | B4: FY27E–FY36E (10 yrs) | F4: Fiscal year ends 31 March. 10-year explicit period because Blinkit/District margins and growth are still ramping; a 5-year DCF would put most value in a terminal year that has not reached steady state.
A6: VALUATION ASSUMPTIONS
A7: Risk-Free Rate | B7: 0.067 | F7: ASSUMPTION from market data: India 10-yr G-sec ~6.7% (Trading Economics, 7-Jul-2026). Refresh before publishing.
A8: Equity Risk Premium | B8: 0.055 | F8: ASSUMPTION: Indian equity risk premium (INR basis, Rf already embeds sovereign spread). Typical practitioner range 5.0–6.5%.
A9: Beta | B9: 1.2 | F9: ASSUMPTION: no regression run. High-volatility consumer-internet stock; TO VERIFY against Bloomberg / NSE 2-yr weekly beta vs Nifty.
A10: Cost of Equity | B10: =B7+B9*B8 -> 0.133 | F10: CAPM: Rf + Beta × ERP.
A11: Pre-Tax Cost of Debt | B11: 0.09 | F11: ASSUMPTION: Eternal has no financial debt (Mar-2026 balance sheet); only lease liabilities. Cost of debt only matters if debt weight > 0.
A12: Tax Rate | B12: 0.2517 | F12: Indian corporate tax rate, new regime (22% + surcharge + cess = 25.17%).
A13: WACC | B13: =(1-B14)*B10+B14*B11*(1-B12) -> 0.133 | F13: WACC. With zero debt weight, WACC = cost of equity.
A14: Target Debt / (Debt + Equity) | B14: 0 | F14: ASSUMPTION: zero. Leases are treated as operating cost (rent is deducted inside Adjusted EBITDA), so lease liabilities are NOT added to debt.
A15: TERMINAL VALUE
A16: Terminal Growth Rate | B16: 0.05 | F16: ASSUMPTION: long-run nominal INR growth for a mature consumer platform; below FY36E segment growth and below India nominal GDP.
A18: MARKET DATA & EQUITY BRIDGE
A19: Current share price (₹) | B19: 316.8 | F19: REPORTED (secondary): ₹316.80 on NSE, 17-Sep-2026, Anand Rathi share-price page. REFRESH to latest close before publishing.
A20: Shares outstanding — listed, incl. ESOP-trust pool (crore) | B20: 966.75 | F20: DERIVED: ₹919 cr paid-up capital at ₹1 face value (Mar-2026 balance sheet) + 47.75 cr shares allotted to Foodie Bay ESOP Trust (FY25 note 5). Vendor market caps imply ~961–965 cr. Using the higher count = conservative (full dilution).
A21: Market capitalisation (₹ crore) | B21: =B19*B20 -> 306266.4 | F21: Calculated.
A22: Cash & treasury investments (₹ crore) | B22: 18288 | F22: REPORTED: company cash balance incl. treasury bonds/government securities, 30-Jun-2026 (Q1 FY27 shareholder letter, via press). Q4 FY26: 17,972.
A23: Financial debt (₹ crore) | B23: 0 | F23: REPORTED: no borrowings on Mar-2026 consolidated balance sheet.
A24: Contingent GST demands on delivery charges (₹ crore) | B24: 447 | F24: REPORTED: orders/SCNs 420+8+13+6 (Note 6, Q4 FY26 results). Management contests; deducted in full as a conservative haircut.
A25: Valuation date (balance-sheet date of cash) | B25: 46203 | F25: Cash is as at 30-Jun-2026, so DCF is struck at that date and only 9 months of FY27E cash flow is counted.
A26: FY27 year-end | B26: 46477
A27: FY27E stub fraction (share of FY27E cash flow still to come) | B27: =(B26-B25)/365 -> 0.75068493 | F27: Calculated.
A28: USD / INR (for cross-checks only) | B28: 94.6 | F28: DERIVED from HSIE report (market cap ₹2,442 bn = US$25,818 mn, Apr-2026). Used only to compare with management USD guidance.
A30: SCENARIO SELECTOR
A31: Active scenario (1 = Bear, 2 = Base, 3 = Bull) | B31: 2 | F31: Change this cell and every sheet re-computes. Scenario tables on the Valuation sheet marked STATIC were produced by running all three settings.
A32: Active scenario name | B32: =CHOOSE(B31,"Bear","Base","Bull") -> Base
A34: OPERATING DRIVERS | B34: Live | C34: Bear | D34: Base | E34: Bull | F34: Basis / source
A35: Food delivery (Zomato)
A36: NOV growth FY27E | B36: =CHOOSE($B$31,C36,D36,E36) -> 0.2 | C36: 0.15 | D36: 0.2 | E36: 0.22 | F36: Q1 FY27 actual +20.1% YoY; management expects 20%+ trend (Q4 FY26 letter, Q7). Bear = competition (Swiggy Toing / Rapido Ownly) slows growth.
A37: NOV growth FY36E (linear fade from FY27E) | B37: =CHOOSE($B$31,C37,D37,E37) -> 0.08 | C37: 0.06 | D37: 0.08 | E37: 0.09 | F37: ASSUMPTION: fade to India nominal consumption growth+. Growth_t = g0 + (gT−g0)×(t−1)/9.
A38: Adj. EBITDA margin target (% of NOV) | B38: =CHOOSE($B$31,C38,D38,E38) -> 0.06 | C38: 0.05 | D38: 0.06 | E38: 0.07 | F38: FY26 actual 5.3%; Q1 FY27 5.6%; management guides 5–6% range (Q4 FY26 letter). Bull assumes ad/platform-fee mix lifts above range.
A39: Years to reach margin target | B39: =CHOOSE($B$31,C39,D39,E39) -> 3 | C39: 3 | D39: 3 | E39: 3 | F39: ASSUMPTION: straight-line from FY26 actual.
A40: Take rate (adjusted revenue % of NOV) | B40: 0.325 | F40: FY26 actual 30.8%, Q4 FY26 32.0%, Q1 FY27 32.8%. Held flat just above Q4 level.
A41: Quick commerce (Blinkit)
A42: NOV growth FY27E | B42: =CHOOSE($B$31,C42,D42,E42) -> 0.7 | C42: 0.55 | D42: 0.7 | E42: 0.8 | F42: Q1 FY27 +86% YoY. Management: NOV CAGR "north of 60%" for 3 yrs, >4x in 3 yrs (Q4 FY26 letter, Q2). Base 70% fade gives ~63% FY26–29 CAGR.
A43: NOV growth FY36E (linear fade) | B43: =CHOOSE($B$31,C43,D43,E43) -> 0.06 | C43: 0.05 | D43: 0.06 | E43: 0.08 | F43: ASSUMPTION.
A44: Adj. EBITDA margin target (% of NOV) | B44: =CHOOSE($B$31,C44,D44,E44) -> 0.05 | C44: 0.035 | D44: 0.05 | E44: 0.06 | F44: FY26 actual −0.6%; Q1 FY27 +0.6%; management steady-state target raised to 6% (Q1 FY27 call, via Business Standard); earlier 5–6%. Base haircuts to 5%.
...

Sheet Historical
A1: ETERNAL LTD. — HISTORICAL INCOME STATEMENT (₹ crore, consolidated)
A2: Blue = hardcoded Reported input | Black = formula (Calculated) | Yellow = still to pull from filings
A3: Fiscal Year | B3: FY21 | C3: FY22 | D3: FY23 | E3: FY24 | F3: FY25 | G3: FY26
A4: Source / Status | B4: Revenue only. SECONDARY (Screener.in consolidated). Verify vs AR FY22 comparative column. | C4: Revenue only. Business Standard / Inc42 report 4,192.4 (matches Screener). Line items TO PULL from AR FY22 (BSE). | D4: Reported — Zomato AR FY24, Consolidated Statement of P&L, comparative column (FY23). Read via Scribd copy of the AR; confirm vs official PDF. | E4: Reported — Zomato AR FY24, Consolidated Statement of P&L (FY24). Delivery charges: AR FY24 MD&A (3,915). Read via Scribd copy of the AR. | F4: Reported — Eternal Q4FY26 results filing (28-Apr-2026), consolidated P&L, comparative column (FY25, audited). | G4: Reported — Eternal Q4FY26 results filing (28-Apr-2026), consolidated P&L (FY26, audited). Deloitte unmodified opinion.
A6: Revenue from operations | B6: 1994 | C6: 4192 | D6: 7079 | E6: 12114 | F6: 20243 | G6: 54364
A7: Other income | D7: 682 | E7: 847 | F7: 1077 | G7: 1396
A8: Total income | D8: =D6+D7 -> 7761 | E8: =E6+E7 -> 12961 | F8: =F6+F7 -> 21320 | G8: =G6+G7 -> 55760
A10: Cost of materials consumed | D10: 0 | E10: 0 | F10: 0 | G10: 54
A11: Purchases of stock-in-trade | D11: 1438 | E11: 2887 | F11: 5653 | G11: 32115
A12: Changes in inventories | D12: -43 | E12: -5 | F12: -88 | G12: -2002
A13: Employee benefit expense | D13: 1465 | E13: 1659 | F13: 2558 | G13: 3536
A14: Other expenses (total; see memo rows 28-30) | D14: 5429 | E14: 7531 | F14: =SUM(F28:F30) -> 11483 | G14: =SUM(G28:G30) -> 19453
A15: Total operating expenses (before D&A, finance cost) | D15: =SUM(D10:D14) -> 8289 | E15: =SUM(E10:E14) -> 12072 | F15: =SUM(F10:F14) -> 19606 | G15: =SUM(G10:G14) -> 53156
A17: EBITDA (excl. other income) | D17: =D6-D15 -> -1210 | E17: =E6-E15 -> 42 | F17: =F6-F15 -> 637 | G17: =G6-G15 -> 1208
A18: Depreciation and amortisation | D18: 437 | E18: 526 | F18: 863 | G18: 1597
A19: Finance costs | D19: 49 | E19: 72 | F19: 154 | G19: 392
A20: Profit before tax | D20: =D8-D15-D18-D19 -> -1014 | E20: =E8-E15-E18-E19 -> 291 | F20: =F8-F15-F18-F19 -> 697 | G20: =G8-G15-G18-G19 -> 615
A21: Tax expense / (credit) | D21: =D20-D35 -> -43 | E21: =E20-E35 -> -60 | F21: =231-61 -> 170 | G21: =319-70 -> 249
A22: Profit after tax | D22: =D20-D21 -> -971 | E22: =E20-E21 -> 351 | F22: =F20-F21 -> 527 | G22: =G20-G21 -> 366
A24: EBITDA margin | D24: =D17/D6 -> -0.1709281 | E24: =E17/E6 -> 0.0034670629 | F24: =F17/F6 -> 0.031467668 | G24: =G17/G6 -> 0.022220587
A25: Revenue growth (YoY) | C25: =C6/B6-1 -> 1.1023069 | D25: =D6/C6-1 -> 0.68869275 | E25: =E6/D6-1 -> 0.71125865 | F25: =F6/E6-1 -> 0.67104177 | G25: =G6/F6-1 -> 1.6855703
A27: MEMO — OTHER EXPENSES BREAKDOWN (as disclosed)
A28: Advertisement and sales promotion | F28: 1972 | G28: 3350
A29: Delivery and related charges | E29: 3915 | F29: 5728 | G29: 9065
A30: Others | F30: 3783 | G30: 7038
A32: TIE-OUT TO REPORTED FIGURES
A33: Reported profit before tax | E33: 291 | F33: 697 | G33: 615
A34: Difference (calculated − reported) | E34: =E20-E33 -> 0 | F34: =F20-F33 -> 0 | G34: =G20-G33 -> 0
A35: Reported profit after tax | D35: -971 | E35: 351 | F35: 527 | G35: 366
A36: Difference (calculated − reported) | D36: =D22-D35 -> 0 | E36: =E22-E35 -> 0 | F36: =F22-F35 -> 0 | G36: =G22-G35 -> 0
A38: NOTES
A39: 1. Blinkit (Grofers) was consolidated from Aug-2022 (about 8 months in FY23, full year from FY24). FY23 vs FY22 is NOT like-for-like.
A40: 2. Paytm entertainment ticketing (now part of District) consolidated from 27-Aug-2024. FY25 and FY26 are not like-for-like with FY24.
A41: 3. From Q1 FY26 Blinkit moved from marketplace to inventory-led (1P). Revenue now includes full goods value, so FY26 revenue (+168.6%) is inflated; purchases of stock-in-trade jump to 32,115. Company reports like-for-like Adjusted Revenue growth of ~64-65% YoY in Q2-Q4 FY26. Use LFL/NOV in forecasts, not headline growth.
A42: 4. EBITDA here = revenue − operating expenses, excluding other income, D&A and finance cost. It INCLUDES ESOP expense and Ind AS 116 lease effects. Company "Adjusted EBITDA" adds back ESOP expense and deducts lease rentals, so the two will differ. Do not mix them.
A43: 5. FY23 and FY24 tax is backed out as PBT − reported PAT (tax line not separately read), so the PAT tie-out is zero by construction for those two years. FY25/FY26 tax is reported (current + deferred), so their tie-out is a genuine check.
A44: 6. FY25/FY26 "Other expenses" = sum of the three disclosed lines (memo rows). FY23/FY24 are the single reported total. FY24 delivery charges (3,915) is from AR FY24 MD&A; ad and others split not yet pulled.
A45: 7. Cost of materials consumed: first appears in Q3 FY26 (Blinkit Foods / Bistro). Nil in prior years.
A46: 8. TO DO: FY21 and FY22 line items (yellow). Pull from AR FY22 comparative columns on BSE (scrip 543320). Secondary sources disagree on FY22 total expenses (5,908 vs 6,205), so do not fill from aggregators.

Sheet Operating Model
A1: ETERNAL LTD. — OPERATING MODEL (₹ crore unless stated)
A2: Quarterly FY24Q4–FY26Q4: SECONDARY — HDFC Securities (HSIE) Q4FY26 results review, INR mn ÷ 10, compiled from company shareholder letters. Q1 FY27: company shareholder letter as reported in press (Business Standard, X/@NSuresh_ECW, Inc42). VERIFY against official PDFs before publishing.
A3: FY25A / FY26A = sum of four quarters. All segment figures use the company's Adjusted EBITDA definition: EBITDA + share-based payment − Ind AS 116 lease rentals.
A4: Metric | B4: Q4 FY24 | C4: Q1 FY25 | D4: Q2 FY25 | E4: Q3 FY25 | F4: Q4 FY25 | G4: Q1 FY26 | H4: Q2 FY26 | I4: Q3 FY26 | J4: Q4 FY26 | K4: Q1 FY27 | L4: FY25A | M4: FY26A | N4: Source / status
A5: NET ORDER VALUE (NOV), ₹ crore
A6: Food delivery | B6: 7189 | C6: 7928 | D6: 8281 | E6: 8443 | F6: 8210 | G6: 8967 | H6: 9423 | I6: 9846 | J6: 9757 | K6: 10769 | L6: =SUM(C6:F6) -> 32862 | M6: =SUM(G6:J6) -> 37993 | N6: HSIE table "NoV (B2C business)"; Q1 FY27 from company letter (press).
A7: Quick commerce (Blinkit) | B7: 3336 | C7: 4061 | D7: 4928 | E7: 6020 | F7: 7362 | G7: 9203 | H7: 11679 | I7: 13300 | J7: 14386 | K7: 17132 | L7: =SUM(C7:F7) -> 22371 | M7: =SUM(G7:J7) -> 48568
A8: Going-out (District) | B8: 840 | C8: 1031 | D8: 1562 | E8: 2158 | F8: 1868 | G8: 2013 | H8: 2063 | I8: 2587 | J8: 2736 | K8: 3218 | L8: =SUM(C8:F8) -> 6619 | M8: =SUM(G8:J8) -> 9399
A9: Total B2C NOV | B9: =SUM(B6:B8) -> 11365 | C9: =SUM(C6:C8) -> 13020 | D9: =SUM(D6:D8) -> 14771 | E9: =SUM(E6:E8) -> 16621 | F9: =SUM(F6:F8) -> 17440 | G9: =SUM(G6:G8) -> 20183 | H9: =SUM(H6:H8) -> 23165 | I9: =SUM(I6:I8) -> 25733 | ... M9: =SUM(M6:M8) -> 95960
A11: ADJUSTED REVENUE, ₹ crore
A12: Food delivery | B12: 2050 | C12: 2256 | D12: 2340 | E12: 2413 | F12: 2409 | G12: 2657 | H12: 2863 | I12: 3053 | J12: 3125 | K12: 3537 | L12: =SUM(C12:F12) -> 9418 | M12: =SUM(G12:J12) -> 11698
A13: Hyperpure (B2B supplies) | B13: 951 | C13: 1212 | D13: 1473 | E13: 1671 | F13: 1840 | G13: 2295 | H13: 1023 | I13: 1070 | J13: 978 | K13: 1034 | L13: =SUM(C13:F13) -> 6196 | M13: =SUM(G13:J13) -> 5366
A14: Quick commerce (Blinkit) | B14: 769 | C14: 942 | D14: 1156 | E14: 1399 | F14: 1709 | G14: 2400 | H14: 9891 | I14: 12256 | J14: 13232 | K14: 15664 | L14: =SUM(C14:F14) -> 5206 | M14: =SUM(G14:J14) -> 37779 | N14: FY25 5,206 and FY26 37,779 tie exactly to statutory quick-commerce segment revenue (Q4 FY26 filing).
A15: Going-out (District) | B15: 93 | C15: 95 | D15: 154 | E15: 259 | F15: 229 | G15: 207 | H15: 189 | I15: 300 | J15: 277 | K15: 318 | L15: =SUM(C15:F15) -> 737 | M15: =SUM(G15:J15) -> 973
A16: Others | B16: 10 | C16: 15 | D16: 4 | E16: 4 | F16: 1 | G16: 4 | H16: 2 | I16: 13 | J16: 68 | K16: 95 | L16: =SUM(C16:F16) -> 24 | M16: =SUM(G16:J16) -> 87
A17: Total adjusted revenue | B17: =SUM(B12:B16) -> 3873 | C17: =SUM(C12:C16) -> 4520 | D17: =SUM(D12:D16) -> 5127 | E17: =SUM(E12:E16) -> 5746 | F17: =SUM(F12:F16) -> 6188 | G17: =SUM(G12:G16) -> 7563 | H17: =SUM(H12:H16) -> 13968 | I17: =SUM(I12:I16) -> 16692 | ... M17: =SUM(M12:M16) -> 55903
A19: ADJUSTED EBITDA, ₹ crore
A20: Food delivery | B20: 275 | C20: 313 | D20: 341 | E20: 423 | F20: 428 | G20: 451 | H20: 503 | I20: 531 | J20: 532 | K20: 606 | L20: =SUM(C20:F20) -> 1505 | M20: =SUM(G20:J20) -> 2017
A21: Hyperpure (B2B supplies) | B21: -23 | C21: -22 | D21: -21 | E21: -19 | F21: -22 | G21: -18 | H21: -5 | I21: 1 | J21: 5 | K21: 6 | L21: =SUM(C21:F21) -> -84 | M21: =SUM(G21:J21) -> -17
A22: Quick commerce (Blinkit) | B22: -37 | C22: -3 | D22: -8 | E22: -103 | F22: -178 | G22: -162 | H22: -156 | I22: 4 | J22: 37 | K22: 102 | L22: =SUM(C22:F22) -> -292 | M22: =SUM(G22:J22) -> -277
A23: Going-out (District) | B23: -11 | C23: 10 | D23: 16 | E23: -17 | F23: -47 | G23: -54 | H23: -63 | I23: -121 | J23: -81 | K23: -65 | L23: =SUM(C23:F23) -> -38 | M23: =SUM(G23:J23) -> -319
A24: Others | B24: -10 | C24: 1 | D24: 2 | E24: 1 | F24: -16 | G24: -45 | H24: -55 | I24: -51 | J24: -64 | K24: -94 | L24: =SUM(C24:F24) -> -12 | M24: =SUM(G24:J24) -> -215
A25: Total Adjusted EBITDA (sum of segments) | B25: =SUM(B20:B24) -> 194 | C25: =SUM(C20:C24) -> 299 | D25: =SUM(D20:D24) -> 330 | E25: =SUM(E20:E24) -> 285 | F25: =SUM(F20:F24) -> 165 | G25: =SUM(G20:G24) -> 172 | H25: =SUM(H20:H24) -> 224 | I25: =SUM(I20:I24) -> 364 | ... M25: =SUM(M20:M24) -> 1189
A26: Company-reported consolidated Adj. EBITDA (check) | B26: 194 | C26: 299 | D26: 330 | E26: 285 | F26: 165 | G26: 172 | H26: 224 | I26: 364 | J26: 429 | K26: 555 | L26: =SUM(C26:F26) -> 1079 | M26: =SUM(G26:J26) -> 1189 | N26: HSIE "Total Adjusted EBITDA"; FY26 11,890 mn = ₹1,189 cr. Q1 FY27 ₹555 cr per company.
A27: Difference (sum of segments − reported) | B27: =B25-B26 -> 0 | C27: =C25-C26 -> 0 | D27: =D25-D26 -> 0 | E27: =E25-E26 -> 0 | F27: =F25-F26 -> 0 | G27: =G25-G26 -> 0 | H27: =H25-H26 -> 0 | I27: =I25-I26 -> 0 | ... M27: =M25-M26 -> 0
A29: MARGINS & TAKE RATES (calculated)
A30: Food delivery Adj. EBITDA % of NOV | B30: =B20/B6 -> 0.038252886 | C30: =C20/C6 -> 0.039480323 | D30: =D20/D6 -> 0.041178602 | E30: =E20/E6 -> 0.050100675 | F30: =F20/F6 -> 0.052131547 | G30: =G20/G6 -> 0.050295528 | H30: =H20/H6 -> 0.053380028 | I30: =I20/I6 -> 0.05393053 | ... M30: =M20/M6 -> 0.053088727
A31: Blinkit Adj. EBITDA % of NOV | B31: =B22/B7 -> -0.011091127 | C31: =C22/C7 -> -0.0007387343 | D31: =D22/D7 -> -0.0016233766 | E31: =E22/E7 -> -0.017109635 | F31: =F22/F7 -> -0.024178212 | G31: =G22/G7 -> -0.017602956 | H31: =H22/H7 -> -0.013357308 | I31: =I22/I7 -> 0.00030075188 | ... M31: =M22/M7 -> -0.0057033438
A32: District Adj. EBITDA % of NOV | B32: =B23/B8 -> -0.013095238 | C32: =C23/C8 -> 0.009699321 | D32: =D23/D8 -> 0.010243278 | E32: =E23/E8 -> -0.0078776645 | F32: =F23/F8 -> -0.0251606 | G32: =G23/G8 -> -0.026825633 | H32: =H23/H8 -> -0.030538051 | I32: =I23/I8 -> -0.046772323 | ... M32: =M23/M8 -> -0.033939781
A33: Food delivery take rate (adj. revenue % NOV) | B33: =B12/B6 -> 0.28515788 | C33: =C12/C6 -> 0.28456105 | D33: =D12/D6 -> 0.28257457 | E33: =E12/E6 -> 0.28579889 | F33: =F12/F6 -> 0.29342266 | G33: =G12/G6 -> 0.29630869 | H33: =H12/H6 -> 0.30383105 | I33: =I12/I6 -> 0.31007516 | ... M33: =M12/M6 -> 0.30789882
A34: Blinkit take rate (adj. revenue % NOV) | B34: =B14/B7 -> 0.23051559 | C34: =C14/C7 -> 0.23196257 | D34: =D14/D7 -> 0.23457792 | E34: =E14/E7 -> 0.23239203 | F34: =F14/F7 -> 0.23213801 | G34: =G14/G7 -> 0.26078453 | H34: =H14/H7 -> 0.8469047 | I34: =I14/I7 -> 0.92150376 | ... M34: =M14/M7 -> 0.77785785 | N34: Jumps from ~23% to ~92% in Q2 FY26 because Blinkit moved to inventory-led (1P) model — revenue now includes goods sold.
A35: District take rate (adj. revenue % NOV) | B35: =B15/B8 -> 0.11071429 | C35: =C15/C8 -> 0.09214355 | D35: =D15/D8 -> 0.098591549 | E35: =E15/E8 -> 0.12001854 | F35: =F15/F8 -> 0.12259101 | G35: =G15/G8 -> 0.10283159 | H35: =H15/H8 -> 0.091614154 | I35: =I15/I8 -> 0.11596444 | ... M35: =M15/M8 -> 0.10352165
A37: OPERATING KPIs (as disclosed; blank = not found in sources)
A38: Food delivery avg monthly transacting customers (mn) | F38: 20.9 | G38: 22.9 | I38: 24.9 | J38: 25.4 | K38: 27.2 | N38: HSIE KPI table + company letters. Q2 FY26 and Q3 FY25 not found.
A39: Blinkit avg monthly transacting customers (mn) | F39: 13.7 | G39: 16.9 | I39: 23.6 | J39: 27.2 | K39: 31.8
A40: Blinkit orders (mn) | F40: 141.7 | G40: 176.7 | I40: 243.3 | J40: 273.9 | K40: 331
A41: Blinkit net AOV (₹) | F41: 520 | G41: 521 | I41: 547 | J41: 525 | K41: 518
A42: Blinkit stores (period end) | G42: 1544 | I42: 2027 | J42: 2243 | K42: 2443 | N42: Mgmt target 3,000 dark stores by Mar-2027 (HSIE). Q1 FY26 1,544 per press.
A43: Food delivery contribution profit (₹ cr) | F43: 842 | I43: 1023 | J43: 998 | N43: HSIE KPI table (INR mn ÷ 10). Contribution = revenue − order-level variable costs (company definition).
A44: Blinkit contribution profit (₹ cr) | F44: 289 | I44: 736 | J44: 782
...

Sheet Valuation
A1: ETERNAL LTD. — VALUATION (₹ crore unless stated)
A2: ="DCF & SOTP | active scenario: "&Assumptions!B32&" | valuation date "&TEXT(Assumptions!B25,"dd-mmm-yyyy") -> DCF & SOTP | active scenario: Base | valuation date 30-Jun-2026
A3: Basis: pre-Ind AS 116 (lease rent is inside Adjusted EBITDA; lease liabilities excluded from debt). SBC deducted as a real cost. Cash flows exclude treasury income (cash is added in the equity bridge).
A4: DISCOUNTED CASH FLOW | C4: FY26A | D4: FY27E | E4: FY28E | F4: FY29E | G4: FY30E | H4: FY31E | I4: FY32E | J4: FY33E | K4: FY34E | L4: FY35E | M4: FY36E
A5: B2C NOV | C5: ='Operating Model'!C106 -> 95960 | D5: ='Operating Model'!D106 -> 141315.8 | E5: ='Operating Model'!E106 -> 206531.78 | F5: ='Operating Model'!F106 -> 296785.36 | G5: ='Operating Model'!G106 -> 415803.56 | H5: ='Operating Model'!H106 -> 563812.5 | I5: ='Operating Model'!I106 -> 735272.28 | J5: ='Operating Model'!J106 -> 917203.95 | ... M5: ='Operating Model'!M106 -> 1302818.9
A6: Adjusted revenue | C6: ='Operating Model'!C108 -> 55903 | D6: ='Operating Model'!D108 -> 96983.222 | E6: ='Operating Model'!E108 -> 149185.38 | F6: ='Operating Model'!F108 -> 223213.92 | G6: ='Operating Model'!G108 -> 322576.18 | H6: ='Operating Model'!H108 -> 447672.15 | I6: ='Operating Model'!I108 -> 593722.74 | J6: ='Operating Model'!J108 -> 749227.81 | ... M6: ='Operating Model'!M108 -> 1072977.2
A7: Adjusted EBITDA (pre-SBC, post lease rent) | C7: ='Operating Model'!C110 -> 1189 | D7: ='Operating Model'!D110 -> 2391.0673 | E7: ='Operating Model'!E110 -> 4796.7061 | F7: ='Operating Model'!F110 -> 9186.6154 | G7: ='Operating Model'!G110 -> 16351.382 | H7: ='Operating Model'!H110 -> 27373.77 | I7: ='Operating Model'!I110 -> 35566.619 | J7: ='Operating Model'!J110 -> 44258.178 | ... M7: ='Operating Model'!M110 -> 62757.983
A8: SBC (% of B2C NOV) | D8: =Assumptions!$B$64+(Assumptions!$B$65-Assumptions!$B$64)*('Operating Model'!D$77-1)/9 -> 0.0085 | E8: =Assumptions!$B$64+(Assumptions!$B$65-Assumptions!$B$64)*('Operating Model'!E$77-1)/9 -> 0.0081111111 | F8: =Assumptions!$B$64+(Assumptions!$B$65-Assumptions!$B$64)*('Operating Model'!F$77-1)/9 -> 0.0077222222 | G8: =Assumptions!$B$64+(Assumptions!$B$65-Assumptions!$B$64)*('Operating Model'!G$77-1)/9 -> 0.0073333333 | H8: =Assumptions!$B$64+(Assumptions!$B$65-Assumptions!$B$64)*('Operating Model'!H$77-1)/9 -> 0.0069444444 | I8: =Assumptions!$B$64+(Assumptions!$B$65-Assumptions!$B$64)*('Operating Model'!I$77-1)/9 -> 0.0065555556 | J8: =Assumptions!$B$64+(Assumptions!$B$65-Assumptions!$B$64)*('Operating Model'!J$77-1)/9 -> 0.0061666667 | K8: =Assumptions!$B$64+(Assumptions!$B$65-Assumptions!$B$64)*('Operating Model'!K$77-1)/9 -> 0.0057777778 | ... M8: =Assumptions!$B$64+(Assumptions!$B$65-Assumptions!$B$64)*('Operating Model'!M$77-1)/9 -> 0.005
A9: Less: share-based payment | D9: =-D5*D8 -> -1201.1843 | E9: =-E5*E8 -> -1675.2022 | F9: =-F5*F8 -> -2291.8425 | G9: =-G5*G8 -> -3049.2261 | H9: =-H5*H8 -> -3915.3646 | I9: =-I5*I8 -> -4820.1183 | J9: =-J5*J8 -> -5656.091 | K9: =-K5*K8 -> -6293.0878 | ... M9: =-M5*M8 -> -6514.0943
A10: EBITDA after SBC | D10: =D7+D9 -> 1189.883 | E10: =E7+E9 -> 3121.5039 | F10: =F7+F9 -> 6894.7729 | G10: =G7+G9 -> 13302.156 | H10: =H7+H9 -> 23458.405 | I10: =I7+I9 -> 30746.501 | J10: =J7+J9 -> 38602.087 | K10: =K7+K9 -> 46187.938 | ... M10: =M7+M9 -> 56243.889
A11: D&A excl. ROU (% of B2C NOV) | D11: =Assumptions!$B$68+(Assumptions!$B$69-Assumptions!$B$68)*('Operating Model'!D$77-1)/9 -> 0.012 | E11: =Assumptions!$B$68+(Assumptions!$B$69-Assumptions!$B$68)*('Operating Model'!E$77-1)/9 -> 0.011888889 | F11: =Assumptions!$B$68+(Assumptions!$B$69-Assumptions!$B$68)*('Operating Model'!F$77-1)/9 -> 0.011777778 | G11: =Assumptions!$B$68+(Assumptions!$B$69-Assumptions!$B$68)*('Operating Model'!G$77-1)/9 -> 0.011666667 | H11: =Assumptions!$B$68+(Assumptions!$B$69-Assumptions!$B$68)*('Operating Model'!H$77-1)/9 -> 0.011555556 | I11: =Assumptions!$B$68+(Assumptions!$B$69-Assumptions!$B$68)*('Operating Model'!I$77-1)/9 -> 0.011444444 | J11: =Assumptions!$B$68+(Assumptions!$B$69-Assumptions!$B$68)*('Operating Model'!J$77-1)/9 -> 0.011333333 | K11: =Assumptions!$B$68+(Assumptions!$B$69-Assumptions!$B$68)*('Operating Model'!K$77-1)/9 -> 0.011222222 | ... M11: =Assumptions!$B$68+(Assumptions!$B$69-Assumptions!$B$68)*('Operating Model'!M$77-1)/9 -> 0.011
A12: Less: D&A | D12: =-D5*D11 -> -1695.7896 | E12: =-E5*E11 -> -2455.4334 | F12: =-F5*F11 -> -3495.472 | G12: =-G5*G11 -> -4851.0415 | H12: =-H5*H11 -> -6515.1667 | I12: =-I5*I11 -> -8414.7827 | J12: =-J5*J11 -> -10394.978 | K12: =-K5*K11 -> -12223.113 | ... M12: =-M5*M11 -> -14331.007
A13: EBIT | D13: =D10+D12 -> -505.9066 | E13: =E10+E12 -> 666.07056 | F13: =F10+F12 -> 3399.3009 | G13: =G10+G12 -> 8451.1144 | H13: =H10+H12 -> 16943.238 | I13: =I10+I12 -> 22331.718 | J13: =J10+J12 -> 28207.109 | K13: =K10+K12 -> 33964.825 | ... M13: =M10+M12 -> 41912.881
A14: EBIT margin (% of adjusted revenue) | D14: =D13/D6 -> -0.0052164342 | E14: =E13/E6 -> 0.0044647173 | F14: =F13/F6 -> 0.015228893 | G14: =G13/G6 -> 0.026198817 | H14: =H13/H6 -> 0.037847425 | I14: =I13/I6 -> 0.037613041 | J14: =J13/J6 -> 0.037648241 | K14: =K13/K6 -> 0.037909547 | ... M14: =M13/M6 -> 0.039062229
A15: Tax rate on EBIT | D15: =Assumptions!$B$12 -> 0.2517 | E15: =Assumptions!$B$12 -> 0.2517 | F15: =Assumptions!$B$12 -> 0.2517 | G15: =Assumptions!$B$12 -> 0.2517 | H15: =Assumptions!$B$12 -> 0.2517 | I15: =Assumptions!$B$12 -> 0.2517 | J15: =Assumptions!$B$12 -> 0.2517 | K15: =Assumptions!$B$12 -> 0.2517 | ... M15: =Assumptions!$B$12 -> 0.2517
A16: Less: tax on EBIT (nil if EBIT < 0) | D16: =-MAX(0,D13)*D15 -> 0 | E16: =-MAX(0,E13)*E15 -> -167.64996 | F16: =-MAX(0,F13)*F15 -> -855.60404 | G16: =-MAX(0,G13)*G15 -> -2127.1455 | H16: =-MAX(0,H13)*H15 -> -4264.6131 | I16: =-MAX(0,I13)*I15 -> -5620.8934 | J16: =-MAX(0,J13)*J15 -> -7099.7293 | K16: =-MAX(0,K13)*K15 -> -8548.9465 | ... M16: =-MAX(0,M13)*M15 -> -10549.472
A17: NOPAT | D17: =D13+D16 -> -505.9066 | E17: =E13+E16 -> 498.4206 | F17: =F13+F16 -> 2543.6969 | G17: =G13+G16 -> 6323.9689 | H17: =H13+H16 -> 12678.625 | I17: =I13+I16 -> 16710.824 | J17: =J13+J16 -> 21107.38 | K17: =K13+K16 -> 25415.879 | ... M17: =M13+M16 -> 31363.409
A18: Add: D&A | D18: =-D12 -> 1695.7896 | E18: =-E12 -> 2455.4334 | F18: =-F12 -> 3495.472 | G18: =-G12 -> 4851.0415 | H18: =-H12 -> 6515.1667 | I18: =-I12 -> 8414.7827 | J18: =-J12 -> 10394.978 | K18: =-K12 -> 12223.113 | ... M18: =-M12 -> 14331.007
A19: Capex (% of B2C NOV) | D19: =Assumptions!$B$66+(Assumptions!$B$67-Assumptions!$B$66)*('Operating Model'!D$77-1)/9 -> 0.018 | E19: =Assumptions!$B$66+(Assumptions!$B$67-Assumptions!$B$66)*('Operating Model'!E$77-1)/9 -> 0.017333333 | F19: =Assumptions!$B$66+(Assumptions!$B$67-Assumptions!$B$66)*('Operating Model'!F$77-1)/9 -> 0.016666667 | G19: =Assumptions!$B$66+(Assumptions!$B$67-Assumptions!$B$66)*('Operating Model'!G$77-1)/9 -> 0.016 | H19: =Assumptions!$B$66+(Assumptions!$B$67-Assumptions!$B$66)*('Operating Model'!H$77-1)/9 -> 0.015333333 | I19: =Assumptions!$B$66+(Assumptions!$B$67-Assumptions!$B$66)*('Operating Model'!I$77-1)/9 -> 0.014666667 | J19: =Assumptions!$B$66+(Assumptions!$B$67-Assumptions!$B$66)*('Operating Model'!J$77-1)/9 -> 0.014 | K19: =Assumptions!$B$66+(Assumptions!$B$67-Assumptions!$B$66)*('Operating Model'!K$77-1)/9 -> 0.013333333 | ... M19: =Assumptions!$B$66+(Assumptions!$B$67-Assumptions!$B$66)*('Operating Model'!M$77-1)/9 -> 0.012
A20: Less: capex | D20: =-D5*D19 -> -2543.6844 | E20: =-E5*E19 -> -3579.8842 | F20: =-F5*F19 -> -4946.4226 | G20: =-G5*G19 -> -6652.857 | H20: =-H5*H19 -> -8645.1251 | I20: =-I5*I19 -> -10783.993 | J20: =-J5*J19 -> -12840.855 | K20: =-K5*K19 -> -14522.51 | ... M20: =-M5*M19 -> -15633.826
A21: Increase in B2C NOV | D21: =D5-C5 -> 45355.8 | E21: =E5-D5 -> 65215.978 | F21: =F5-E5 -> 90253.58 | G21: =G5-F5 -> 119018.2 | H21: =H5-G5 -> 148008.94 | I21: =I5-H5 -> 171459.77 | J21: =J5-I5 -> 181931.67 | K21: =K5-J5 -> 171984.32 | ... M21: =M5-L5 -> 76850.696
A22: Less: working-capital investment | D22: =-D21*Assumptions!$B$70 -> -453.558 | E22: =-E21*Assumptions!$B$70 -> -652.15978 | F22: =-F21*Assumptions!$B$70 -> -902.5358 | G22: =-G21*Assumptions!$B$70 -> -1190.182 | H22: =-H21*Assumptions!$B$70 -> -1480.0894 | I22: =-I21*Assumptions!$B$70 -> -1714.5977 | J22: =-J21*Assumptions!$B$70 -> -1819.3167 | K22: =-K21*Assumptions!$B$70 -> -1719.8432 | ... M22: =-M21*Assumptions!$B$70 -> -768.50696
A23: Unlevered free cash flow (UFCF) | D23: =D17+D18+D20+D22 -> -1807.3594 | E23: =E17+E18+E20+E22 -> -1278.19 | F23: =F17+F18+F20+F22 -> 190.21045 | G23: =G17+G18+G20+G22 -> 3331.9714 | H23: =H17+H18+H20+H22 -> 9068.5774 | I23: =I17+I18+I20+I22 -> 12627.016 | J23: =J17+J18+J20+J22 -> 16842.186 | K23: =K17+K18+K20+K22 -> 21396.638 | ... M23: =M17+M18+M20+M22 -> 29292.083
A25: Share of year included (FY27E = stub) | D25: =Assumptions!$B$27 -> 0.75068493 | E25: 1 | F25: 1 | G25: 1 | H25: 1 | I25: 1 | J25: 1 | K25: 1 | L25: 1 | M25: 1
A26: Discount period (years, mid-year) | D26: =D25/2 -> 0.37534247 | E26: =Assumptions!$B$27+('Operating Model'!E$77-2)+0.5 -> 1.2506849 | F26: =Assumptions!$B$27+('Operating Model'!F$77-2)+0.5 -> 2.2506849 | G26: =Assumptions!$B$27+('Operating Model'!G$77-2)+0.5 -> 3.2506849 | H26: =Assumptions!$B$27+('Operating Model'!H$77-2)+0.5 -> 4.2506849 | I26: =Assumptions!$B$27+('Operating Model'!I$77-2)+0.5 -> 5.2506849 | J26: =Assumptions!$B$27+('Operating Model'!J$77-2)+0.5 -> 6.2506849 | K26: =Assumptions!$B$27+('Operating Model'!K$77-2)+0.5 -> 7.2506849 | L26: =Assumptions!$B$27+('Operating Model'!L$77-2)+0.5 -> 8.2506849 | M26: =Assumptions!$B$27+('Operating Model'!M$77-2)+0.5 -> 9.2506849
A27: Discount factor | D27: =1/(1+Assumptions!$B$13)^D26 -> 0.95421274 | E27: =1/(1+Assumptions!$B$13)^E26 -> 0.85541226 | F27: =1/(1+Assumptions!$B$13)^F26 -> 0.75499758 | G27: =1/(1+Assumptions!$B$13)^G26 -> 0.66637033 | H27: =1/(1+Assumptions!$B$13)^H26 -> 0.5881468 | I27: =1/(1+Assumptions!$B$13)^I26 -> 0.51910574 | J27: =1/(1+Assumptions!$B$13)^J26 -> 0.45816923 | K27: =1/(1+Assumptions!$B$13)^K26 -> 0.40438591 | ... M27: =1/(1+Assumptions!$B$13)^M26 -> 0.31501859
A28: PV of UFCF | D28: =D23*D25*D27 -> -1294.6353 | E28: =E23*E25*E27 -> -1093.3794 | F28: =F23*F25*F27 -> 143.60843 | G28: =G23*G25*G27 -> 2220.3269 | H28: =H23*H25*H27 -> 5333.6548 | I28: =I23*I25*I27 -> 6554.7565 | J28: =J23*J25*J27 -> 7716.5712 | K28: =K23*K25*K27 -> 8652.4988 | ... M28: =M23*M25*M27 -> 9227.5509
A30: DCF VALUATION SUMMARY
A31: WACC | B31: =Assumptions!B13 -> 0.133
A32: Terminal growth | B32: =Assumptions!B16 -> 0.05
A33: Sum of PV of UFCF (FY27E stub – FY36E) | B33: =SUM(D28:M28) -> 46657.435
A34: Terminal-year UFCF (FY36E) | B34: =M23 -> 29292.083
A35: Terminal value at FY36E (Gordon growth) | B35: =IF(B31>B32,M23*(1+B32)/(B31-B32),NA()) -> 370562.5
A36: PV of terminal value | B36: =B35*M27 -> 116734.08 | C36: TV discounted with the FY36E mid-year factor (consistent with Gordon growth on mid-year flows).
A37: Enterprise value | B37: =B33+B36 -> 163391.51
A38: Add: cash & treasury investments | B38: =Assumptions!B22 -> 18288
A39: Less: financial debt | B39: =-Assumptions!B23 -> 0
A40: Less: contingent GST demands | B40: =-Assumptions!B24 -> -447
A41: Equity value | B41: =SUM(B37:B40) -> 181232.51
A42: Shares outstanding (crore) | B42: =Assumptions!B20 -> 966.75
...

Sheet Mini Projects
A1: ETERNAL LTD. — MINI-PROJECTS
A2: Tags: R = Reported (company disclosure) | C = Calculated from reported figures | D = Derived estimate | A = Assumption (judgement; NOT disclosed) | N/D = not disclosed / not found. Blue = input, black = formula, green = link.
A4: MINI-PROJECT 1 — WHAT IS ONE ZOMATO CUSTOMER WORTH? (food-delivery customer LTV)
A5: Input | B5: Value | C5: Unit | D5: Tag | G5: Source / logic
A6: Food-delivery avg monthly transacting customers, Q4 FY26 | B6: 25.4 | C6: mn | D6: R | G6: Q4 FY26 shareholder letter via HSIE / press.
A7: Food-delivery avg monthly transacting customers, Q1 FY27 | B7: 27.2 | C7: mn | D7: R | G7: Q1 FY27 results (press).
A8: FY25 food-delivery orders | B8: 853 | C8: mn | D8: R | G8: Annual Report FY25 (via MediaNama).
A9: FY25 average monthly transacting customers | B9: 20.6 | C9: mn | D9: R | G9: Annual Report FY25 (via MediaNama).
A10: FY25 orders per customer per month | B10: =B8/(B9*12) -> 3.4506472 | C10: x | D10: C | G10: Orders ÷ (MTU × 12).
A11: Forward orders per customer per month | B11: 3.4 | C11: x | D11: A | G11: Anchored to FY25 calc (3.45). Management: food-delivery frequency stable for several quarters (Q4 FY26 letter, Q7).
A12: FY25 food-delivery NOV | B12: ='Operating Model'!L6 -> 32862 | C12: ₹ cr | D12: C | G12: Operating Model quarterly sum.
A13: FY25 net AOV (NOV ÷ orders) | B13: =B12*10/B8 -> 385.25205 | C13: ₹ | D13: C | G13: NOV × 10 ÷ orders (₹ cr → ₹ mn).
A14: Forward net AOV | B14: 380 | C14: ₹ | D14: A | G14: Management is deliberately lowering AOV (₹99 free-delivery threshold, meals <₹250). Q4 FY26 implied: 9,757 cr ÷ (25.4 mn × 3.4 × 3) ≈ ₹377 (D).
A15: Take rate (adjusted revenue % of NOV), Q4 FY26 | B15: ='Operating Model'!J33 -> 0.32028287 | C15: % | D15: C | G15: Operating Model: adjusted revenue ÷ NOV.
A16: Contribution margin (% of NOV), Q4 FY26 | B16: ='Operating Model'!J45 -> 0.10228554 | C16: % | D16: C | G16: Operating Model: contribution profit ÷ NOV (company-defined contribution).
A17: Adjusted EBITDA margin (% of NOV), Q4 FY26 | B17: ='Operating Model'!J30 -> 0.054524956 | C17: % | D17: C | G17: Fully-loaded view: includes tech, corporate and marketing not allocated to orders.
A18: Annual customer retention (share of customers still ordering next year) | B18: 0.7 | C18: % | D18: A | G18: NOT DISCLOSED. Eternal does not publish cohort retention. TO IMPROVE with cohort data if ever disclosed.
A19: Annual growth in contribution per order | B19: 0.05 | C19: % | D19: A | G19: ASSUMPTION: inflation / take-rate gains.
A20: Discount rate | B20: =Assumptions!B13 -> 0.133 | C20: % | D20: A | G20: Model WACC.
A21: Customer-life horizon cap | B21: 7 | C21: years | D21: A | G21: ASSUMPTION.
A22: Customer acquisition cost (CAC) | B22: 250 | C22: ₹ | D22: A | G22: NOT DISCLOSED. Group advertising & promotion (₹3,350 cr FY26) cannot be split by segment or new vs existing customers. Placeholder; see sensitivity.
A24: Output | B24: Value | C24: Unit | D24: Tag
A25: Orders per customer per year | B25: =B11*12 -> 40.8 | C25: orders | D25: C
A26: Adjusted revenue per order | B26: =B14*B15 -> 121.70749 | C26: ₹ | D26: C | G26: Net AOV × take rate.
A27: Contribution per order | B27: =B14*B16 -> 38.868505 | C27: ₹ | D27: C | G27: Net AOV × contribution margin.
A28: Adj. EBITDA per order (fully loaded) | B28: =B14*B17 -> 20.719483 | C28: ₹ | D28: C
A29: Year-1 contribution per customer | B29: =B25*B27 -> 1585.835 | C29: ₹ | D29: C | G29: Orders/yr × contribution/order.
A30: Year-1 fully-loaded EBITDA per customer | B30: =B25*B28 -> 845.35492 | C30: ₹ | D30: C
A31: Cohort decay factor a = retention × (1+growth) ÷ (1+discount) | B31: =B18*(1+B19)/(1+B20) -> 0.64872021 | C31: x | D31: C
A32: Annuity factor Σ a^(t−1), t = 1..N | B32: =IF(B31=1,B21,(1-B31^B21)/(1-B31)) -> 2.7090923 | C32: x | D32: C | G32: Closed form (1−a^N)/(1−a).
A33: CUSTOMER LTV — contribution basis (before CAC) | B33: =B29/(1+B20)^0.5*B32 -> 4036.1458 | C33: ₹ | D33: C | G33: Year-1 contribution ÷ (1+r)^0.5 × annuity factor (mid-year).
A34: LTV net of CAC — contribution basis | B34: =B33-B22 -> 3786.1458 | C34: ₹ | D34: C
A35: LTV / CAC | B35: =B33/B22 -> 16.144583 | C35: x | D35: C | G35: Rule of thumb >3x healthy.
A36: LTV — fully-loaded Adj. EBITDA basis (before CAC) | B36: =B30/(1+B20)^0.5*B32 -> 2151.5327 | C36: ₹ | D36: C | G36: Conservative floor.
A37: LTV net of CAC — fully-loaded basis | B37: =B36-B22 -> 1901.5327 | C37: ₹ | D37: C
A38: Implied expected customer lifetime | B38: =1/(1-B18) -> 3.3333333 | C38: years | D38: C | G38: 1 ÷ (1 − retention).
A39: Value of current active base (LTV × Q1 FY27 customers) | B39: =B33*B7/10 -> 10978.317 | C39: ₹ cr | D39: C | G39: ₹ × mn ÷ 10.
A40: Food-delivery EV in SOTP (PV today) | B40: =Valuation!G64 -> 87768.988 | C40: ₹ cr | D40: C
A41: SOTP food-delivery EV ÷ value of existing base (x) | B41: =B40/B39 -> 7.9947582 | C41: x | D41: C | G41: Market pays this multiple of the existing base LTV for growth, new cohorts and pricing power.
A43: LTV sensitivity (₹, contribution basis, before CAC): retention (down) vs orders per month (across)
...

Sheet Sources
A1: ETERNAL LTD. — SOURCES, DATA STATUS AND OPEN ITEMS
A3: # | B3: Item | C3: Used for | D3: Type | E3: Source / URL / caveat
A4: 1 | B4: Eternal Q4 FY26 shareholder letter + audited FY26 results (28-Apr-2026) | C4: FY25/FY26 P&L, segment revenue, segment note, cash flow, balance sheet, GST contingencies, guidance | D4: Primary | E4: https://b.zmtcdn.com/investor-relations/Eternal_Limited_Shareholders_Letter_Q4FY26_Results.pdf (Deloitte unmodified opinion). Tables extracted from PDF text; OCR noise checked by arithmetic tie-out.
A5: 2 | B5: HDFC Securities (HSIE) — Eternal 4QFY26 results review (29-Apr-2026) | C5: Quarterly segment NOV, adjusted revenue, Adj. EBITDA, KPIs (FY24Q4–FY26Q4); SOTP reference multiples | D5: Secondary | E5: https://www.hdfcsec.com/hsl.docs//Eternal%20-%20Q4FY26%20-%20HSIE-202604290654005590303.pdf — INR mn ÷ 10. FY25/FY26 sums tie to company: Adj. EBITDA 1,079 / 1,189; quick-commerce revenue 5,206 / 37,779. TO VERIFY quarter-by-quarter against company letters.
A6: 3 | B6: Eternal Q1 FY27 results (22-Jul-2026), via press | C6: Q1 FY27 NOV, Adj. EBITDA, MTU, orders, stores, cash ₹18,288 cr | D6: Secondary | E6: Business Standard (22/23-Jul-2026); X post @NSuresh_ECW; Inc42; MediaNama earnings-call takeaways; Indian Startup News. Segment sum 606+6+102−65−94 = 555 ties to reported total. TO PULL official Q1 FY27 shareholder letter from eternal.com/investor-relations.
A7: 4 | B7: Eternal Annual Report FY25 (via MediaNama / Storyboard18) | C7: FY25 food-delivery orders (853 mn), AOV, MTU (20.6 mn), Blinkit orders | D7: Secondary | E7: https://www.medianama.com/2025/07/223-eternal-fy25-annual-report-highlights-zomato-blinkit/
A8: 5 | B8: Swiggy Q1 FY27 shareholder letter (Jul-2026) | C8: Swiggy MTU, platform MTU, Instamart orders / AOV / MTU, B2C orders | D8: Primary (snippets) | E8: https://www.swiggy.com/corporate/wp-content/uploads/2026/07/Q1-FY2027-Shareholder-letter.pdf — read via search-result excerpts of the key-metrics tables; column order Q1 FY26 → Q1 FY27. TO VERIFY by opening the PDF.
A9: 6 | B9: Swiggy Q1 FY27 press coverage | C9: Swiggy FD GOV 9,490, adj. EBITDA 292, Instamart GOV 7,907 / NOV 5,817 / EBITDA −778, B2C GOV 18,926 | D9: Secondary | E9: Inc42, BW Marketing World, Business Standard, ViE Stories, YourStory, Medianama (Aug-2026).
A10: 7 | B10: Share price ₹316.80 (17-Sep-2026) | C10: Market cap, upside/downside | D10: Secondary | E10: https://anandrathi.com/stocks/eternal-ltd/share-price-today — REFRESH to latest close.
A11: 8 | B11: India 10-yr G-sec yield ~6.7% (7-Jul-2026) | C11: Risk-free rate | D11: Secondary | E11: https://tradingeconomics.com/india/government-bond-yield/news/564773 — REFRESH.
A12: 9 | B12: ERP 5.5%, beta 1.20, terminal growth 5%, all operating drivers on Assumptions | C12: WACC and forecast | D12: ASSUMPTION | E12: Judgement. Beta and ERP are NOT sourced from a data vendor.
A13: 10 | B13: Mini-project 1 retention, CAC, forward frequency, AOV | C13: Customer LTV | D13: ASSUMPTION | E13: Not disclosed by Eternal. Sensitivity grids show the range.
A14: 11 | B14: Mini-project 2 advertiser penetration, spend, margin | C14: Advertising economics | D14: ASSUMPTION | E14: Ad revenue is not disclosed separately; model is scenario-based.
B16: OPEN ITEMS / KNOWN LIMITATIONS
B17: • Historical sheet FY21 and FY22 line items are still blank (needs the FY22 annual report on BSE, scrip 543320). Left untouched; the model does not depend on them.
B18: • FY25 lease-rental plug (356) differs from FY25 cash lease payments (405) by 49; FY26 ties exactly. Not forced — definitional difference.
B19: • Hyperpure FY26 revenue (5,366) includes non-restaurant sales later moved to Blinkit (1P). FY27E revenue is therefore a reset input, not a growth rate.
B20: • D&A excluding right-of-use assets is a proxy (total D&A − lease principal paid). ROU depreciation is not separately extracted.
B21: • Tax is applied to EBIT from FY27E even though carried-forward losses shelter part of it (management says fully used in FY27) — conservative.
B22: • Share count 966.75 cr includes the ESOP-trust pool; consolidated paid-up capital is 919 cr. Per-share values are ~5% lower than on 919 cr.
B23: • Swiggy "114.5 mn food-delivery orders" in one press summary is actually Instamart orders; rejected and Swiggy food orders derived instead.
B24: • Eternal food-delivery orders / GOV for FY26 and Q1 FY27 not found — Mini-project 1 uses a forward-frequency assumption anchored on FY25 disclosures.
B25: • Static tables (scenario summary, sensitivities 2–3) are pasted values from running the model; they do not update when inputs change. Re-run by switching the selector on Assumptions.
